<?xml version="1.0"?>
<robot name="josjisbot" xmlns:xacro="http://www.ros.org/wiki/xacro">

	<link name="base_footprint"/>
	<link name="base_link">
		<visual>
			<origin xyz="0 0 0" rpy="0 0 0"/>
			<geometry>
				<box size="0.4 0.4 0.1"/>
			</geometry>
			<material name="blue">
				<color rgba="0.2 0.2 0.8 1.0"/>
			</material>
		</visual>
		<collision>
			<origin xyz="0 0 0" rpy="0 0 0"/>
			<geometry>
				<box size="0.4 0.4 0.1"/>
			</geometry>
		</collision>
		<inertial>
			<origin xyz="0 0 0" rpy="0 0 0"/>
			<mass value="5.0"/>
			<inertia ixx="0.133" ixy="0.0" ixz="0.0"
				iyy="0.133" iyz="0.0"
				izz="0.133"/>
		</inertial>
	</link>

	<link name="wheel_fr">
		<visual>
			<origin xyz="0 0 0" rpy="1.57 0 0"/>
			<geometry>
				<cylinder radius="0.05" length="0.03"/>
			</geometry>
			<material name="black">
				<color rgba="0.2 0.2 0.2 1.0"/>
			</material>
		</visual>
		<collision>
			<origin xyz="0 0 0" rpy="1.57 0 0"/>
			<geometry>
				<cylinder radius="0.05" length="0.03"/>
			</geometry>
		</collision>
		<inertial>
			<origin xyz="0 0 0" rpy="0 0 0"/>
			<mass value="0.2"/>
			<inertia ixx="0.0003" ixy="0.0" ixz="0.0"
				iyy="0.0005" iyz="0.0"
				izz="0.0005"/>
		</inertial>
	</link>
	<link name="wheel_fl">
		<visual>
			<origin xyz="0 0 0" rpy="1.57 0 0"/>
			<geometry>
				<cylinder radius="0.05" length="0.03"/>
			</geometry>
			<material name="black">
				<color rgba="0.2 0.2 0.2 1.0"/>
			</material>
		</visual>
		<collision>
			<origin xyz="0 0 0" rpy="1.57 0 0"/>
			<geometry>
				<cylinder radius="0.05" length="0.03"/>
			</geometry>
		</collision>
		<inertial>
			<origin xyz="0 0 0" rpy="0 0 0"/>
			<mass value="0.2"/>
			<inertia ixx="0.0003" ixy="0.0" ixz="0.0"
				iyy="0.0005" iyz="0.0"
				izz="0.0005"/>
		</inertial>
	</link>
	<link name="wheel_bl">
		<visual>
			<origin xyz="0 0 0" rpy="1.57 0 0"/>
			<geometry>
				<cylinder radius="0.05" length="0.03"/>
			</geometry>
			<material name="black">
				<color rgba="0.2 0.2 0.2 1.0"/>
			</material>
		</visual>
		<collision>
			<origin xyz="0 0 0" rpy="1.57 0 0"/>
			<geometry>
				<cylinder radius="0.05" length="0.03"/>
			</geometry>
		</collision>
		<inertial>
			<origin xyz="0 0 0" rpy="0 0 0"/>
			<mass value="0.2"/>
			<inertia ixx="0.0003" ixy="0.0" ixz="0.0"
				iyy="0.0005" iyz="0.0"
				izz="0.0005"/>
		</inertial>
	</link>
	<link name="wheel_br">
		<visual>
			<origin xyz="0 0 0" rpy="1.57 0 0"/>
			<geometry>
				<cylinder radius="0.05" length="0.03"/>
			</geometry>
			<material name="black">
				<color rgba="0.2 0.2 0.2 1.0"/>
			</material>
		</visual>
		<collision>
			<origin xyz="0 0 0" rpy="1.57 0 0"/>
			<geometry>
				<cylinder radius="0.05" length="0.03"/>
			</geometry>
		</collision>
		<inertial>
			<origin xyz="0 0 0" rpy="0 0 0"/>
			<mass value="0.2"/>
			<inertia ixx="0.0003" ixy="0.0" ixz="0.0"
				iyy="0.0005" iyz="0.0"
				izz="0.0005"/>
		</inertial>
	</link>

	<joint name="base_joint" type="fixed">
		<parent link="base_footprint"/>
		<child link="base_link" />
		<origin xyz="0 0 0.05" rpy="0 0 0"/>
	</joint>

  <joint name="wheel_fr_joint" type="continuous">
    <parent link="base_link"/>
    <child link="wheel_fr"/>
    <origin xyz="0.141 0.141 0" rpy="0 0 0.785"/>
    <axis xyz="-1 0 0"/>
    <dynamics damping="0.1" friction="0.1"/>
  </joint>

  <joint name="wheel_fl_joint" type="continuous">
    <parent link="base_link"/>
    <child link="wheel_fl"/>
    <origin xyz="-0.141 0.141 0" rpy="0 0 2.356"/>
    <axis xyz="-1 0 0"/>
    <dynamics damping="0.1" friction="0.1"/>
  </joint>

  <joint name="wheel_bl_joint" type="continuous">
    <parent link="base_link"/>
    <child link="wheel_bl"/>
    <origin xyz="-0.141 -0.141 0" rpy="0 0 3.927"/>
    <axis xyz="-1 0 0"/>
    <dynamics damping="0.1" friction="0.1"/>
  </joint>

  <joint name="wheel_br_joint" type="continuous">
    <parent link="base_link"/>
    <child link="wheel_br"/>
    <origin xyz="0.141 -0.141 0" rpy="0 0 5.498"/>
    <axis xyz="-1 0 0"/>
    <dynamics damping="0.1" friction="0.1"/>
  </joint>

</robot>
